2019-10-11 23:22:56 ERROR [88561-Thread-2] log.log_response line 228: Internal Server Error: /
Traceback (most recent call last):
  File "/Users/xiaohuge/PycharmProjects/Python-camp/oa/venv/lib/python3.7/site-packages/django/core/handlers/exception.py", line 34, in inner
    response = get_response(request)
  File "/Users/xiaohuge/PycharmProjects/Python-camp/oa/venv/lib/python3.7/site-packages/debug_toolbar/middleware.py", line 92, in __call__
    panel.generate_stats(request, response)
  File "/Users/xiaohuge/PycharmProjects/Python-camp/oa/venv/lib/python3.7/site-packages/debug_toolbar/panels/staticfiles.py", line 128, in generate_stats
    "staticfiles_finders": self.get_staticfiles_finders(),
  File "/Users/xiaohuge/PycharmProjects/Python-camp/oa/venv/lib/python3.7/site-packages/debug_toolbar/panels/staticfiles.py", line 140, in get_staticfiles_finders
    for path, finder_storage in finder.list([]):
  File "/Users/xiaohuge/PycharmProjects/Python-camp/oa/venv/lib/python3.7/site-packages/django/contrib/staticfiles/finders.py", line 125, in list
    for path in utils.get_files(storage, ignore_patterns):
  File "/Users/xiaohuge/PycharmProjects/Python-camp/oa/venv/lib/python3.7/site-packages/django/contrib/staticfiles/utils.py", line 23, in get_files
    directories, files = storage.listdir(location)
  File "/Users/xiaohuge/PycharmProjects/Python-camp/oa/venv/lib/python3.7/site-packages/django/core/files/storage.py", line 313, in listdir
    for entry in os.listdir(path):
FileNotFoundError: [Errno 2] No such file or directory: '/Users/xiaohuge/PycharmProjects/Python-camp/oa/static'
2019-10-11 23:22:56 ERROR [88561-Thread-2] basehttp.log_message line 154: "GET / HTTP/1.1" 500 87625
2019-10-11 23:24:39 ERROR [88596-Thread-2] log.log_response line 228: Internal Server Error: /
Traceback (most recent call last):
  File "/Users/xiaohuge/PycharmProjects/Python-camp/oa/venv/lib/python3.7/site-packages/django/core/handlers/exception.py", line 34, in inner
    response = get_response(request)
  File "/Users/xiaohuge/PycharmProjects/Python-camp/oa/venv/lib/python3.7/site-packages/debug_toolbar/middleware.py", line 92, in __call__
    panel.generate_stats(request, response)
  File "/Users/xiaohuge/PycharmProjects/Python-camp/oa/venv/lib/python3.7/site-packages/debug_toolbar/panels/staticfiles.py", line 128, in generate_stats
    "staticfiles_finders": self.get_staticfiles_finders(),
  File "/Users/xiaohuge/PycharmProjects/Python-camp/oa/venv/lib/python3.7/site-packages/debug_toolbar/panels/staticfiles.py", line 140, in get_staticfiles_finders
    for path, finder_storage in finder.list([]):
  File "/Users/xiaohuge/PycharmProjects/Python-camp/oa/venv/lib/python3.7/site-packages/django/contrib/staticfiles/finders.py", line 125, in list
    for path in utils.get_files(storage, ignore_patterns):
  File "/Users/xiaohuge/PycharmProjects/Python-camp/oa/venv/lib/python3.7/site-packages/django/contrib/staticfiles/utils.py", line 23, in get_files
    directories, files = storage.listdir(location)
  File "/Users/xiaohuge/PycharmProjects/Python-camp/oa/venv/lib/python3.7/site-packages/django/core/files/storage.py", line 313, in listdir
    for entry in os.listdir(path):
FileNotFoundError: [Errno 2] No such file or directory: '/Users/xiaohuge/PycharmProjects/Python-camp/oa/static'
2019-10-11 23:24:39 ERROR [88596-Thread-2] basehttp.log_message line 154: "GET / HTTP/1.1" 500 87625
2019-10-11 23:25:06 ERROR [88608-Thread-2] log.log_response line 228: Internal Server Error: /
Traceback (most recent call last):
  File "/Users/xiaohuge/PycharmProjects/Python-camp/oa/venv/lib/python3.7/site-packages/django/core/handlers/exception.py", line 34, in inner
    response = get_response(request)
  File "/Users/xiaohuge/PycharmProjects/Python-camp/oa/venv/lib/python3.7/site-packages/debug_toolbar/middleware.py", line 92, in __call__
    panel.generate_stats(request, response)
  File "/Users/xiaohuge/PycharmProjects/Python-camp/oa/venv/lib/python3.7/site-packages/debug_toolbar/panels/staticfiles.py", line 128, in generate_stats
    "staticfiles_finders": self.get_staticfiles_finders(),
  File "/Users/xiaohuge/PycharmProjects/Python-camp/oa/venv/lib/python3.7/site-packages/debug_toolbar/panels/staticfiles.py", line 140, in get_staticfiles_finders
    for path, finder_storage in finder.list([]):
  File "/Users/xiaohuge/PycharmProjects/Python-camp/oa/venv/lib/python3.7/site-packages/django/contrib/staticfiles/finders.py", line 125, in list
    for path in utils.get_files(storage, ignore_patterns):
  File "/Users/xiaohuge/PycharmProjects/Python-camp/oa/venv/lib/python3.7/site-packages/django/contrib/staticfiles/utils.py", line 23, in get_files
    directories, files = storage.listdir(location)
  File "/Users/xiaohuge/PycharmProjects/Python-camp/oa/venv/lib/python3.7/site-packages/django/core/files/storage.py", line 313, in listdir
    for entry in os.listdir(path):
FileNotFoundError: [Errno 2] No such file or directory: '/Users/xiaohuge/PycharmProjects/Python-camp/oa/static'
2019-10-11 23:25:06 ERROR [88608-Thread-2] basehttp.log_message line 154: "GET / HTTP/1.1" 500 87199
2019-10-11 23:26:40 ERROR [88636-Thread-2] log.log_response line 228: Internal Server Error: /
Traceback (most recent call last):
  File "/Users/xiaohuge/PycharmProjects/Python-camp/oa/venv/lib/python3.7/site-packages/django/urls/base.py", line 75, in reverse
    extra, resolver = resolver.namespace_dict[ns]
KeyError: 'djdt'

During handling of the above exception, another exception occurred:

Traceback (most recent call last):
  File "/Users/xiaohuge/PycharmProjects/Python-camp/oa/venv/lib/python3.7/site-packages/django/core/handlers/exception.py", line 34, in inner
    response = get_response(request)
  File "/Users/xiaohuge/PycharmProjects/Python-camp/oa/venv/lib/python3.7/site-packages/debug_toolbar/middleware.py", line 99, in __call__
    bits[-2] += toolbar.render_toolbar()
  File "/Users/xiaohuge/PycharmProjects/Python-camp/oa/venv/lib/python3.7/site-packages/debug_toolbar/toolbar.py", line 69, in render_toolbar
    return render_to_string("debug_toolbar/base.html", context)
  File "/Users/xiaohuge/PycharmProjects/Python-camp/oa/venv/lib/python3.7/site-packages/django/template/loader.py", line 62, in render_to_string
    return template.render(context, request)
  File "/Users/xiaohuge/PycharmProjects/Python-camp/oa/venv/lib/python3.7/site-packages/django/template/backends/django.py", line 61, in render
    return self.template.render(context)
  File "/Users/xiaohuge/PycharmProjects/Python-camp/oa/venv/lib/python3.7/site-packages/django/template/base.py", line 171, in render
    return self._render(context)
  File "/Users/xiaohuge/PycharmProjects/Python-camp/oa/venv/lib/python3.7/site-packages/django/test/utils.py", line 96, in instrumented_test_render
    return self.nodelist.render(context)
  File "/Users/xiaohuge/PycharmProjects/Python-camp/oa/venv/lib/python3.7/site-packages/django/template/base.py", line 937, in render
    bit = node.render_annotated(context)
  File "/Users/xiaohuge/PycharmProjects/Python-camp/oa/venv/lib/python3.7/site-packages/django/template/base.py", line 904, in render_annotated
    return self.render(context)
  File "/Users/xiaohuge/PycharmProjects/Python-camp/oa/venv/lib/python3.7/site-packages/django/template/defaulttags.py", line 309, in render
    return nodelist.render(context)
  File "/Users/xiaohuge/PycharmProjects/Python-camp/oa/venv/lib/python3.7/site-packages/django/template/base.py", line 937, in render
    bit = node.render_annotated(context)
  File "/Users/xiaohuge/PycharmProjects/Python-camp/oa/venv/lib/python3.7/site-packages/django/template/base.py", line 904, in render_annotated
    return self.render(context)
  File "/Users/xiaohuge/PycharmProjects/Python-camp/oa/venv/lib/python3.7/site-packages/django/template/defaulttags.py", line 442, in render
    url = reverse(view_name, args=args, kwargs=kwargs, current_app=current_app)
  File "/Users/xiaohuge/PycharmProjects/Python-camp/oa/venv/lib/python3.7/site-packages/django/urls/base.py", line 86, in reverse
    raise NoReverseMatch("%s is not a registered namespace" % key)
django.urls.exceptions.NoReverseMatch: 'djdt' is not a registered namespace
2019-10-11 23:26:40 ERROR [88636-Thread-2] basehttp.log_message line 154: "GET / HTTP/1.1" 500 131318
2019-10-11 23:26:52 ERROR [88636-Thread-2] log.log_response line 228: Internal Server Error: /vote/
Traceback (most recent call last):
  File "/Users/xiaohuge/PycharmProjects/Python-camp/oa/venv/lib/python3.7/site-packages/django/urls/base.py", line 75, in reverse
    extra, resolver = resolver.namespace_dict[ns]
KeyError: 'djdt'

During handling of the above exception, another exception occurred:

Traceback (most recent call last):
  File "/Users/xiaohuge/PycharmProjects/Python-camp/oa/venv/lib/python3.7/site-packages/django/core/handlers/exception.py", line 34, in inner
    response = get_response(request)
  File "/Users/xiaohuge/PycharmProjects/Python-camp/oa/venv/lib/python3.7/site-packages/debug_toolbar/middleware.py", line 99, in __call__
    bits[-2] += toolbar.render_toolbar()
  File "/Users/xiaohuge/PycharmProjects/Python-camp/oa/venv/lib/python3.7/site-packages/debug_toolbar/toolbar.py", line 69, in render_toolbar
    return render_to_string("debug_toolbar/base.html", context)
  File "/Users/xiaohuge/PycharmProjects/Python-camp/oa/venv/lib/python3.7/site-packages/django/template/loader.py", line 62, in render_to_string
    return template.render(context, request)
  File "/Users/xiaohuge/PycharmProjects/Python-camp/oa/venv/lib/python3.7/site-packages/django/template/backends/django.py", line 61, in render
    return self.template.render(context)
  File "/Users/xiaohuge/PycharmProjects/Python-camp/oa/venv/lib/python3.7/site-packages/django/template/base.py", line 171, in render
    return self._render(context)
  File "/Users/xiaohuge/PycharmProjects/Python-camp/oa/venv/lib/python3.7/site-packages/django/test/utils.py", line 96, in instrumented_test_render
    return self.nodelist.render(context)
  File "/Users/xiaohuge/PycharmProjects/Python-camp/oa/venv/lib/python3.7/site-packages/django/template/base.py", line 937, in render
    bit = node.render_annotated(context)
  File "/Users/xiaohuge/PycharmProjects/Python-camp/oa/venv/lib/python3.7/site-packages/django/template/base.py", line 904, in render_annotated
    return self.render(context)
  File "/Users/xiaohuge/PycharmProjects/Python-camp/oa/venv/lib/python3.7/site-packages/django/template/defaulttags.py", line 309, in render
    return nodelist.render(context)
  File "/Users/xiaohuge/PycharmProjects/Python-camp/oa/venv/lib/python3.7/site-packages/django/template/base.py", line 937, in render
    bit = node.render_annotated(context)
  File "/Users/xiaohuge/PycharmProjects/Python-camp/oa/venv/lib/python3.7/site-packages/django/template/base.py", line 904, in render_annotated
    return self.render(context)
  File "/Users/xiaohuge/PycharmProjects/Python-camp/oa/venv/lib/python3.7/site-packages/django/template/defaulttags.py", line 442, in render
    url = reverse(view_name, args=args, kwargs=kwargs, current_app=current_app)
  File "/Users/xiaohuge/PycharmProjects/Python-camp/oa/venv/lib/python3.7/site-packages/django/urls/base.py", line 86, in reverse
    raise NoReverseMatch("%s is not a registered namespace" % key)
django.urls.exceptions.NoReverseMatch: 'djdt' is not a registered namespace
2019-10-11 23:26:52 ERROR [88636-Thread-2] basehttp.log_message line 154: "GET /vote/ HTTP/1.1" 500 126030
2019-10-11 23:27:33 WARNING [88651-Thread-2] basehttp.log_message line 154: "GET /static/images/hot.png HTTP/1.1" 404 1666
2019-10-11 23:27:56 WARNING [88651-Thread-5] basehttp.log_message line 154: "GET /static/666 HTTP/1.1" 404 1633
